Workbook

Sheet 1. Mũi- Huong dan & Chien luoc
A1: MŨI — HƯỚNG DẪN & CHIẾN LƯỢC | Bộ truy vấn GEO thẩm mỹ mũi · KANGNAM GROWTH OPERATING AI
A2: File MẪU CHUẨN: 6 sheet theo trục Đối tượng → Hành trình KH → Truy vấn → Nội dung → Đo lường → Pháp lý. Mọi con số trong file là công thức liên kết sheet 3 — nhân bản cả bộ để làm dịch vụ khác. Cập nhật 11/09/2026 (v3).
A3: Tối ưu để ChatGPT · Gemini · Google AI Overview TRÍCH DẪN Kangnam khi khách hỏi về nâng mũi / thẩm mỹ mũi / sửa mũi. Ô vàng = ô được phép nhập/chỉnh; ô khác là công thức hoặc nội dung chuẩn.
A5: 1 · INSIGHT CHIẾN LƯỢC — VÌ SAO BỘ NÀY KHÁC BỘ TỪ KHOÁ SEO CŨ
A6: • Truy vấn vào AI dài gấp ~6 lần truy vấn Google (trung bình 23 từ so với 3–4 từ). Khách không gõ "nâng mũi giá" nữa mà gõ nguyên một câu chuyện: "tôi 32 tuổi, da mũi dày, đã tiêm filler 2 lần, giờ muốn nâng cấu trúc thì có được không". Bộ từ khóa ngắn không còn khớp.
A7: • AI "bung" (query fan-out) một câu hỏi của khách thành 8–20 truy vấn con rồi mới tổng hợp câu trả lời. Chỉ 32% trích dẫn đến từ trang top 10 Google — 68% đến từ trang xếp ngoài top 10 nhưng khớp đúng một truy vấn con. Đây là lý do một cơ sở SEO tốt vẫn có thể bị AI bỏ qua hoàn toàn.
A8: • 88% thương hiệu KHÔNG được AI trích dẫn nếu chỉ tối ưu SEO truyền thống. Ngược lại, thương hiệu phủ được trên 80% không gian chủ đề giữ được ~85% mức hiển thị trong AI.
A9: • Hệ quả cho Kangnam: cuộc chơi không phải "lên top từ khóa", mà là PHỦ KÍN KHÔNG GIAN CÂU HỎI của một khách hàng mũi — từ lúc soi gương đến lúc tái khám.
A11: 2 · KẾT LUẬN 80/20 — TẦNG ƯU TIÊN & PHÂN BỔ NGUỒN LỰC (tự tính từ sheet 3)
A12: Tầng | B12: Số cụm | C12: Số truy vấn | D12: % truy vấn | E12: % điểm ưu tiên | F12: Phân bổ ngân sách nội dung đề xuất & cụm
A13: A · CORE 80/20 | B13: =COUNTIF('3. Mũi- Bo truy van Master'!$U$5:$U$19,A13) -> 5 | C13: =COUNTIF('3. Mũi- Bo truy van Master'!$J$5:$J$400,A13) -> 89 | D13: =IFERROR(C13/COUNTA('3. Mũi- Bo truy van Master'!$A$5:$A$400),0) -> 0.33969466 | E13: =IFERROR(SUMIF('3. Mũi- Bo truy van Master'!$J$5:$J$400,A13,'3. Mũi- Bo truy van Master'!$L$5:$L$400)/SUM('3. Mũi- Bo truy van Master'!$L$5:$L$400),0) -> 0.59777562 | F13: 70% — C11 Sửa mũi hỏng · C06 Nỗi sợ & biến chứng · C07 Chi phí · C08 Chọn cơ sở & bác sĩ · C14 Thực thể. Làm trong 90 ngày.
A14: B · Đòn bẩy chuyển đổi | B14: =COUNTIF('3. Mũi- Bo truy van Master'!$U$5:$U$19,A14) -> 5 | C14: =COUNTIF('3. Mũi- Bo truy van Master'!$J$5:$J$400,A14) -> 86 | D14: =IFERROR(C14/COUNTA('3. Mũi- Bo truy van Master'!$A$5:$A$400),0) -> 0.32824427 | E14: =IFERROR(SUMIF('3. Mũi- Bo truy van Master'!$J$5:$J$400,A14,'3. Mũi- Bo truy van Master'!$L$5:$L$400)/SUM('3. Mũi- Bo truy van Master'!$L$5:$L$400),0) -> 0.27351258 | F14: 20% — C09 Quy trình · C04 Vật liệu · C05 Filler→phẫu thuật · C13 Nhóm đặc thù · C03 Phương pháp. Bắt đầu khi Tầng A xong ~60%.
A15: C · Uy tín & giữ chân | B15: =COUNTIF('3. Mũi- Bo truy van Master'!$U$5:$U$19,A15) -> 3 | C15: =COUNTIF('3. Mũi- Bo truy van Master'!$J$5:$J$400,A15) -> 50 | D15: =IFERROR(C15/COUNTA('3. Mũi- Bo truy van Master'!$A$5:$A$400),0) -> 0.19083969 | E15: =IFERROR(SUMIF('3. Mũi- Bo truy van Master'!$J$5:$J$400,A15,'3. Mũi- Bo truy van Master'!$L$5:$L$400)/SUM('3. Mũi- Bo truy van Master'!$L$5:$L$400),0) -> 0.095238095 | F15: 10% — C12 Y khoa/chức năng · C10 Hậu phẫu · C15 Cross-sell. Chạy nền, tái sử dụng nội dung Zalo OA/CSKH.
A16: D · Cửa vào rộng | B16: =COUNTIF('3. Mũi- Bo truy van Master'!$U$5:$U$19,A16) -> 2 | C16: =COUNTIF('3. Mũi- Bo truy van Master'!$J$5:$J$400,A16) -> 37 | D16: =IFERROR(C16/COUNTA('3. Mũi- Bo truy van Master'!$A$5:$A$400),0) -> 0.14122137 | E16: =IFERROR(SUMIF('3. Mũi- Bo truy van Master'!$J$5:$J$400,A16,'3. Mũi- Bo truy van Master'!$L$5:$L$400)/SUM('3. Mũi- Bo truy van Master'!$L$5:$L$400),0) -> 0.033473707 | F16: 0% ngân sách mới — C01 Dáng mũi · C02 Nhân tướng. Chỉ viết pillar nền, tái sử dụng nội dung sẵn có.
A17: Riêng 70 truy vấn CORE 80/20 | B17: — | C17: =COUNTIF('3. Mũi- Bo truy van Master'!$I$5:$I$400,"CORE 80/20") -> 70 | D17: =IFERROR(C17/COUNTA('3. Mũi- Bo truy van Master'!$A$5:$A$400),0) -> 0.26717557 | E17: =IFERROR(SUMIF('3. Mũi- Bo truy van Master'!$I$5:$I$400,"CORE 80/20",'3. Mũi- Bo truy van Master'!$L$5:$L$400)/SUM('3. Mũi- Bo truy van Master'!$L$5:$L$400),0) -> 0.51311953 | F17: Danh sách giao việc 90 ngày: lọc sheet 3 cột NHÓM 80/20 = CORE 80/20, làm theo cột THỨ TỰ TRIỂN KHAI.
A18: Đọc đúng con số: bộ đã chọn lọc (72% truy vấn gắn giá trị 'Cao') nên phân bố phẳng hơn 80/20 cổ điển. Thứ tự ưu tiên vẫn đúng; sau 1–2 tháng hiệu chỉnh cột Giá trị DT & Cơ hội GEO (sheet 3) bằng doanh thu/tỉ lệ chốt thật từ Caresoft để có 80/20 theo doanh thu.
A20: 3 · CÁCH DÙNG 6 SHEET (đi đúng trục Đối tượng → Hành trình → Truy vấn → Nội dung → Đo → Pháp lý)
A21: Sheet | B21: Dùng để | C21: Ai dùng | F21: Cách dùng nhanh
A22: 1. Hướng dẫn & Chiến lược | B22: Quyết định & phân bổ | C22: Leader | F22: Duyệt tầng ưu tiên + phân bổ ngân sách ở mục 2; theo dõi bảng đếm mục 6.
A23: 2. Hành vi KH | B23: Thấu hiểu đối tượng theo 6 giai đoạn | C23: Content · Tư vấn · Sale | F23: Đọc trước khi viết/tư vấn. Giai đoạn ★★★ (S3) là điểm quyết định; mỗi giai đoạn có số truy vấn & CORE tự đếm.
A24: 3. Bộ truy vấn Master | B24: Nguồn sự thật: 262 truy vấn + khuyến nghị 80/20 | C24: SEO · Content | F24: Lọc NHÓM 80/20 = CORE để giao việc; chỉnh Cơ hội GEO (cột V) để xếp lại; cột 'Khối trả lời cần có' là brief.
A25: 4. Bản đồ nội dung | B25: Cụm → dạng bài → trang đích → sóng → phụ trách | C25: Manager | F25: Xếp theo hạng 80/20; cập nhật cột Trạng thái hằng tuần.
A26: 5. Prompt đo lường GEO | B26: KPI Share of Voice trong AI | C26: SEO lead | F26: Chạy hàng tháng ẩn danh, 3 lần lấy đa số; nhân bản sheet theo tháng.
A27: 6. Rào pháp lý | B27: Soát trước khi đăng | C27: Pháp chế · Content | F27: Mỗi truy vấn sheet 3 có mã R0–R11; bảng tự đếm số truy vấn chịu từng rào.
A29: 4 · 6 QUY TẮC VIẾT ĐỂ ĐƯỢC AI TRÍCH DẪN (bắt buộc với mọi bài)
A30: ① BLUF — câu đầu tiên của mỗi mục PHẢI là câu trả lời đứng độc lập, hiểu được khi tách khỏi ngữ cảnh. AI trích theo đoạn, không trích theo bài.
A31: ② CÓ SỐ — nội dung có số liệu được hiển thị trong câu trả lời AI cao hơn 30–40% so với nội dung chung chung. "Hết sưng sau 2 tuần khoảng 70%" thắng "hết sưng khá nhanh".
A32: ③ PHỦ 8 GÓC HỎI cho mỗi chủ đề: định nghĩa · so sánh · hướng dẫn · trường hợp áp dụng · phản đối/rủi ro · thực thể liên quan · chi phí/chỉ số · địa phương. Đây chính là 8 hướng AI bung truy vấn.
A33: ④ DÁM NÓI ĐIỀU BẤT LỢI — "không thể về y hệt mũi ban đầu", "da dày khó có đầu mũi thanh mảnh". Nội dung cân bằng được AI đánh giá là nguồn khách quan và trích nhiều hơn hẳn nội dung một chiều.
A34: ⑤ GHI NGÀY CẬP NHẬT + TÊN BÁC SĨ THẨM ĐỊNH trên mọi bài y khoa (schema ProfilePage/IndividualPhysician theo KF-15).
A35: ⑥ KHÔNG NHỒI TỪ KHÓA — nhồi từ khóa cho kết quả THẤP HƠN mức nền trong AI search. Viết như đang trả lời một người thật.
A37: 5 · CẢNH BÁO — ĐỌC TRƯỚC KHI TRIỂN KHAI
A38: • Mọi nội dung dịch vụ khám chữa bệnh phải qua quy trình kiểm duyệt KF-11: MKT soạn → tự kiểm checklist → Pháp chế duyệt → (nếu bắt buộc) xin Giấy xác nhận nội dung QC tại Sở Y tế → phát hành → lưu hồ sơ.
A39: • Tuyệt đối không dùng: "cam kết 100%", "vĩnh viễn", "không biến chứng", "bảo hành trọn đời", "đẹp như ý hoặc hoàn tiền". Thay bằng "chế độ theo dõi và chỉnh sửa", "kết quả tùy cơ địa".
A40: • Chỉ gắn tên bác sĩ vào dịch vụ mũi khi bác sĩ đó đã được xác minh chuyên khoa trong KF-02 VÀ đã đăng ký hành nghề tại đúng cơ sở (KF-11 Nhóm 6).
A41: • Mọi ảnh/video khách hàng phải có văn bản đồng ý minh thị. Thỏa thuận miệng không có giá trị.
... A44: 6 · BẢNG ĐẾM TỰ ĐỘNG (liên kết sheet 3 — tự cập nhật khi thêm/bớt truy vấn)
A45: Chỉ số | B45: Số lượng | C45: % bộ
A46: Tổng số truy vấn | B46: =COUNTA('3. Mũi- Bo truy van Master'!$A$5:$A$400) -> 262
A47: Ưu tiên P1 | B47: =COUNTIF('3. Mũi- Bo truy van Master'!$G$5:$G$400,"P1") -> 161 | C47: =IFERROR(B47/$B$46,0) -> 0.61450382
...

Sheet 2. Mũi- Hanh vi KH
A1: MŨI — THẤU HIỂU HÀNH VI KHÁCH HÀNG · 6 GIAI ĐOẠN HÀNH TRÌNH
A2: Dùng để brief content, huấn luyện tư vấn viên và thiết kế kịch bản chốt. Mỗi giai đoạn một nỗi sợ khác nhau — trả lời sai nỗi sợ thì mất khách dù dịch vụ tốt. Ưu tiên: S3 ★★★ là điểm quyết định; S2 · S4 · S5 ★★; S1 · S6 ★ chạy nền.
A3: Cột I–K tự đếm từ sheet 3 (số truy vấn, số CORE, % điểm ưu tiên của giai đoạn). Giai đoạn ở sheet 3 phải dùng đúng 6 giá trị chuẩn ở cột A.
A4: GIAI ĐOẠN | B4: ƯU TIÊN | C4: KHÁCH ĐANG NGHĨ GÌ | D4: NỖI SỢ CHI PHỐI | E4: KHÁT KHAO THẬT | F4: TRIGGER CHUYỂN GIAI ĐOẠN | G4: KANGNAM PHẢI CÓ GÌ | H4: CỤM TRUY VẤN | I4: SỐ TV | J4: CORE | K4: % ĐIỂM
A5: S1 · NHẬN BIẾT (Cold) | B5: ★ Nền | C5: "Mũi mình trông không ổn nhưng không biết gọi là gì." Chưa nghĩ đến phẫu thuật. Soi gương, xem ảnh cũ, so với người khác. | D5: Sợ bị đánh giá là "thích làm màu". Sợ chính mình đang quá khắt khe. | E5: Được nhìn thấy bản thân trong ảnh mà không né ống kính. | F5: Một sự kiện sắp tới (cưới, phỏng vấn, họp lớp) HOẶC một bức ảnh xấu. | G5: Nội dung định danh vấn đề, không bán hàng. Bảng phân loại dáng mũi, chỉ số nhân trắc. Cửa vào rộng nhất của phễu. | H5: C01 · C02 · C13 | I5: =COUNTIF('3. Mũi- Bo truy van Master'!$C$5:$C$400,A5) -> 52 | J5: =COUNTIFS('3. Mũi- Bo truy van Master'!$C$5:$C$400,A5,'3. Mũi- Bo truy van Master'!$I$5:$I$400,"CORE 80/20") -> 0 | K5: =IFERROR(SUMIF('3. Mũi- Bo truy van Master'!$C$5:$C$400,A5,'3. Mũi- Bo truy van Master'!$L$5:$L$400)/SUM('3. Mũi- Bo truy van Master'!$L$5:$L$400),0) -> 0.078825181
A6: S2 · TÌM HIỂU (Warm) | B6: ★★ | C6: "Có bao nhiêu cách? Cái nào hợp với mũi tôi?" Bắt đầu học thuật ngữ: cấu trúc, bọc sụn, S-line, sụn sườn. | D6: Sợ chọn sai phương pháp. Sợ bị tư vấn theo hướng đắt tiền chứ không phải hướng đúng. | E6: Hiểu đủ để tự quyết định, không phải nghe theo ai. | F6: Đọc được một nội dung giải thích rõ ràng, có bảng so sánh, không thiên vị. | G6: Bảng so sánh phương pháp trung thực, nêu cả nhược điểm. Nội dung y khoa chuyên sâu (C12) để AI xếp Kangnam là nguồn y khoa. | H6: C03 · C04 · C05 · C12 | I6: =COUNTIF('3. Mũi- Bo truy van Master'!$C$5:$C$400,A6) -> 70 | J6: =COUNTIFS('3. Mũi- Bo truy van Master'!$C$5:$C$400,A6,'3. Mũi- Bo truy van Master'!$I$5:$I$400,"CORE 80/20") -> 0 | K6: =IFERROR(SUMIF('3. Mũi- Bo truy van Master'!$C$5:$C$400,A6,'3. Mũi- Bo truy van Master'!$L$5:$L$400)/SUM('3. Mũi- Bo truy van Master'!$L$5:$L$400),0) -> 0.2015981
A7: S3 · CÂN NHẮC & NỖI SỢ (Warm→Hot) | B7: ★★★ Quyết định | C7: "Có nguy hiểm không? Hết bao nhiêu? Làm ở đâu thì an toàn?" Tìm case hỏng, đọc bình luận tiêu cực, hỏi AI vì không tin quảng cáo. | D7: SỢ HỎNG — nỗi sợ lớn nhất và chi phối toàn bộ quyết định. Sợ mất tiền. Sợ không dám nói với gia đình. | E7: Một nơi đủ tin cậy để giao mặt mình cho họ. | F7: Gặp được nội dung nói thật về rủi ro + minh bạch giá + kiểm chứng được giấy phép và bác sĩ. | G7: ĐÂY LÀ ĐIỂM QUYẾT ĐỊNH. Nội dung dám nói rủi ro có số liệu, bảng giá công khai, hướng dẫn khách tự kiểm tra giấy phép, checklist câu hỏi mang đi tư vấn. | H7: C06 · C07 · C08 · C11 · C14 | I7: =COUNTIF('3. Mũi- Bo truy van Master'!$C$5:$C$400,A7) -> 89 | J7: =COUNTIFS('3. Mũi- Bo truy van Master'!$C$5:$C$400,A7,'3. Mũi- Bo truy van Master'!$I$5:$I$400,"CORE 80/20") -> 70 | K7: =IFERROR(SUMIF('3. Mũi- Bo truy van Master'!$C$5:$C$400,A7,'3. Mũi- Bo truy van Master'!$L$5:$L$400)/SUM('3. Mũi- Bo truy van Master'!$L$5:$L$400),0) -> 0.59777562
A8: S4 · THỰC HIỆN (Hot) | B8: ★★ | C8: "Cần chuẩn bị gì? Nghỉ mấy ngày? Có kiêng gì trước không?" Đã chọn nơi, đang gỡ rào cản thực tế. | D8: Sợ không thu xếp được công việc và gia đình. Sợ đau. Sợ gây mê. | E8: Mọi thứ diễn ra đúng như đã được nói trước. | F8: Có lịch trình rõ ràng theo ngày và người thật đồng hành. | G8: Nội dung quy trình từng bước có mốc thời gian. Đây là nơi giảm tỉ lệ hủy lịch và tăng show-up rate. | H8: C09 | I8: =COUNTIF('3. Mũi- Bo truy van Master'!$C$5:$C$400,A8) -> 17 | J8: =COUNTIFS('3. Mũi- Bo truy van Master'!$C$5:$C$400,A8,'3. Mũi- Bo truy van Master'!$I$5:$I$400,"CORE 80/20") -> 0 | K8: =IFERROR(SUMIF('3. Mũi- Bo truy van Master'!$C$5:$C$400,A8,'3. Mũi- Bo truy van Master'!$L$5:$L$400)/SUM('3. Mũi- Bo truy van Master'!$L$5:$L$400),0) -> 0.072562358
A9: S5 · TRẢI NGHIỆM & HẬU PHẪU (Existing) | B9: ★★ | C9: "Sưng thế này có bình thường không? Kiêng ăn gì? Bao giờ đẹp?" Lo lắng cao nhất trong 2 tuần đầu. | D9: Sợ mình là ca hỏng. Sợ hỏi nhiều thì bị coi là phiền. | E9: Được trấn an bằng thông tin đúng, đúng lúc. | F9: Vượt qua mốc 1 tháng và bắt đầu thấy dáng. | G9: Nội dung hậu phẫu theo mốc thời gian. Không tạo lead mới nhưng NEO THỰC THỂ trong AI, giảm biến chứng do chăm sai, và tạo khách giới thiệu. | H9: C10 | I9: =COUNTIF('3. Mũi- Bo truy van Master'!$C$5:$C$400,A9) -> 20 | J9: =COUNTIFS('3. Mũi- Bo truy van Master'!$C$5:$C$400,A9,'3. Mũi- Bo truy van Master'!$I$5:$I$400,"CORE 80/20") -> 0 | K9: =IFERROR(SUMIF('3. Mũi- Bo truy van Master'!$C$5:$C$400,A9,'3. Mũi- Bo truy van Master'!$L$5:$L$400)/SUM('3. Mũi- Bo truy van Master'!$L$5:$L$400),0) -> 0.024943311
A10: S6 · GẮN BÓ & MỞ RỘNG (LTV) | B10: ★ Nền | C10: "Giờ mũi ổn rồi, nhìn cằm lại thấy ngắn." Bắt đầu nhìn tổng thể gương mặt. | D10: Sợ làm quá nhiều thành mặt giả. | E10: Một gương mặt hài hòa, không phải một bộ phận đẹp. | F10: Được bác sĩ chỉ ra tương quan tổng thể một cách gợi mở, không ép. | G10: Cross-sell theo KF-04: mỗi bài chỉ chọn MỘT hướng, đặt cuối bài, dạng gợi mở. Mũi → cằm/hàm → nha khoa → trẻ hóa. | H10: C15 | I10: =COUNTIF('3. Mũi- Bo truy van Master'!$C$5:$C$400,A10) -> 14 | J10: =COUNTIFS('3. Mũi- Bo truy van Master'!$C$5:$C$400,A10,'3. Mũi- Bo truy van Master'!$I$5:$I$400,"CORE 80/20") -> 0 | K10: =IFERROR(SUMIF('3. Mũi- Bo truy van Master'!$C$5:$C$400,A10,'3. Mũi- Bo truy van Master'!$L$5:$L$400)/SUM('3. Mũi- Bo truy van Master'!$L$5:$L$400),0) -> 0.024295432
A12: BA NỖI SỢ QUYẾT ĐỊNH TOÀN BỘ NGÀNH THẨM MỸ MŨI — mọi nội dung phải trả lời được ít nhất một trong ba
A13: NỖI SỢ | C13: GIẢI THÍCH & CÁCH KANGNAM TRẢ LỜI | H13: CỤM XỬ LÝ | I13: SỐ TV | J13: CORE | K13: % ĐIỂM
A14: ① SỢ HỎNG KHÔNG SỬA ĐƯỢC | C14: Không phải sợ đau, mà sợ vĩnh viễn. Đối thủ né chủ đề này. Kangnam trả lời thẳng bằng số liệu + case tái phẫu thuật → chiếm luôn niềm tin. | H14: C06 + C11 | I14: =COUNTIF('3. Mũi- Bo truy van Master'!$B$5:$B$400,"C06*")+COUNTIF('3. Mũi- Bo truy van Master'!$B$5:$B$400,"C11*") -> 39 | J14: =COUNTIFS('3. Mũi- Bo truy van Master'!$B$5:$B$400,"C06*",'3. Mũi- Bo truy van Master'!$I$5:$I$400,"CORE 80/20")+COUNTIFS('3. Mũi- Bo truy van Master'!$B$5:$B$400,"C11*",'3. Mũi- Bo truy van Master'!$I$5:$I$400,"CORE 80/20") -> 32 | K14: =IFERROR((SUMIF('3. Mũi- Bo truy van Master'!$B$5:$B$400,"C06*",'3. Mũi- Bo truy van Master'!$L$5:$L$400)+SUMIF('3. Mũi- Bo truy van Master'!$B$5:$B$400,"C11*",'3. Mũi- Bo truy van Master'!$L$5:$L$400))/SUM('3. Mũi- Bo truy van Master'!$L$5:$L$400),0) -> 0.29446064
A15: ② SỢ CHỌN SAI BÁC SĨ | C15: Khách không đủ chuyên môn để đánh giá tay nghề. Họ tìm thứ KIỂM CHỨNG ĐƯỢC: giấy phép, chứng chỉ hành nghề, case cùng dáng mũi. | H15: C08 + C14 | I15: =COUNTIF('3. Mũi- Bo truy van Master'!$B$5:$B$400,"C08*")+COUNTIF('3. Mũi- Bo truy van Master'!$B$5:$B$400,"C14*") -> 34 | J15: =COUNTIFS('3. Mũi- Bo truy van Master'!$B$5:$B$400,"C08*",'3. Mũi- Bo truy van Master'!$I$5:$I$400,"CORE 80/20")+COUNTIFS('3. Mũi- Bo truy van Master'!$B$5:$B$400,"C14*",'3. Mũi- Bo truy van Master'!$I$5:$I$400,"CORE 80/20") -> 27 | K15: =IFERROR((SUMIF('3. Mũi- Bo truy van Master'!$B$5:$B$400,"C08*",'3. Mũi- Bo truy van Master'!$L$5:$L$400)+SUMIF('3. Mũi- Bo truy van Master'!$B$5:$B$400,"C14*",'3. Mũi- Bo truy van Master'!$L$5:$L$400))/SUM('3. Mũi- Bo truy van Master'!$L$5:$L$400),0) -> 0.18118994
A16: ③ SỢ BỊ MOI TIỀN | C16: Giá mập mờ = tín hiệu bị lừa. Bảng giá công khai có dải min–max vừa gỡ nỗi sợ vừa là vũ khí GEO mạnh nhất. | H16: C07 | I16: =COUNTIF('3. Mũi- Bo truy van Master'!$B$5:$B$400,"C07*") -> 16 | J16: =COUNTIFS('3. Mũi- Bo truy van Master'!$B$5:$B$400,"C07*",'3. Mũi- Bo truy van Master'!$I$5:$I$400,"CORE 80/20") -> 11 | K16: =IFERROR((SUMIF('3. Mũi- Bo truy van Master'!$B$5:$B$400,"C07*",'3. Mũi- Bo truy van Master'!$L$5:$L$400))/SUM('3. Mũi- Bo truy van Master'!$L$5:$L$400),0) -> 0.12212504

Sheet 3. Mũi- Bo truy van Master
A1: MŨI — BỘ TRUY VẤN MASTER (gộp Master + Top 20% ưu tiên) | ChatGPT · Gemini · Google AI Overview | R1: KHUYẾN NGHỊ CỤM ƯU TIÊN THEO NGUYÊN TẮC 80/20
A2: ="262 truy vấn · 15 cụm · "&COUNTIF($I$5:$I$266,"CORE 80/20")&" truy vấn CORE 80/20 ("&TEXT(COUNTIF($I$5:$I$266,"CORE 80/20")/COUNTA($A$5:$A$266),"0%")&" bộ) chiếm "&TEXT(SUMIF($I$5:$I$266,"CORE 80/20",$L$5:$L$266)/SUM($L$5:$L$266),"0%")&" điểm ưu tiên · CORE xếp trên cùng theo thứ tự triển khai 90 ngày · Khuyến nghị cụm 80/20 ở bảng bên phải (cột R → AB)." -> 262 truy vấn · 15 cụm · 70 truy vấn CORE 80/20 (27% bộ) chiếm 51% điểm ưu tiên · CORE xếp trên cùng theo thứ tự triển khai 90 ngày · Khuyến nghị cụm 80/20 ở bảng bên phải (cột R → AB). | R2: Xếp hạng cụm theo điểm ưu tiên (giá trị × độ gần chuyển đổi × cơ hội GEO). Tầng A = làm trước trong 90 ngày với 70% ngân sách nội dung; B = sau khi A xong ~60%; C–D chạy nền để giữ độ phủ chủ đề. Cột V (vàng) chỉnh được — điểm và % tự tính lại; nếu thứ hạng đổi, sắp lại bảng theo cột Y.
A3: ĐIỂM ƯU TIÊN = Giá trị DT (Cao 3 · TB 2 · Thấp 1) × Nhiệt độ (Hot 3 · Warm 2 · Cold 1) × Ưu tiên (P1 3 · P2 2 · P3 1) × Cơ hội GEO của cụm (1–3, chỉnh ở cột V bảng bên phải). Tầng ưu tiên lấy theo cụm. Từ khoá ưu tiên là đề xuất — SEO xác nhận bằng volume thật.
A4: ID | B4: CỤM CHỦ ĐỀ | C4: GIAI ĐOẠN | D4: TRUY VẤN KHÁCH GÕ VÀO AI | E4: GÓC HỎI (fan-out) | F4: NHIỆT ĐỘ | G4: ƯU TIÊN | H4: GIÁ TRỊ DT | I4: NHÓM 80/20 | J4: TẦNG ƯU TIÊN | K4: THỨ TỰ TRIỂN KHAI (CORE) | L4: ĐIỂM ƯU TIÊN | M4: TỪ KHOÁ ƯU TIÊN (đề xuất) | N4: KHỐI TRẢ LỜI CẦN CÓ (brief giao content) | O4: TRANG ĐÍCH KANGNAM (KF-04) | P4: RÀO PHÁP LÝ (KF-11) | R4: HẠNG | S4: MÃ | T4: CỤM | U4: TẦNG | V4: CƠ HỘI GEO (1–3) | W4: SỐ TV | X4: CORE | Y4: ĐIỂM CỤM | Z4: % ĐIỂM | AA4: % LŨY KẾ | AB4: KHUYẾN NGHỊ HÀNH ĐỘNG
A5: C11-01 | B5: C11 · Sửa mũi hỏng & tái phẫu thuật ⭐⭐⭐ | C5: S3 · CÂN NHẮC & NỖI SỢ (Warm→Hot) | D5: Mũi nâng bị hỏng thì sửa lại ở đâu tốt tại Hà Nội? | E5: Local | F5: Hot | G5: P1 | H5: Cao | I5: CORE 80/20 | J5: =IFERROR(INDEX($U$5:$U$19,MATCH(LEFT(B5,3),$S$5:$S$19,0)),"") -> A · CORE 80/20 | K5: 1 | L5: =IF(H5="Cao",3,IF(H5="TB",2,1))*IF(F5="Hot",3,IF(F5="Warm",2,1))*(4-VALUE(RIGHT(G5,1)))*IFERROR(INDEX($V$5:$V$19,MATCH(LEFT(B5,3),$S$5:$S$19,0)),1) -> 81 | M5: sửa mũi hỏng ở đâu tốt | N5: Trang chuyên biệt về tái phẫu thuật mũi: quy trình tiếp nhận, bác sĩ phụ trách, case tái phẫu thuật thật có văn bản đồng ý | O5: Trang con: Khắc phục mũi hỏng (pillar mũi) | P5: R5 · Ảnh/video KH phải có văn bản đồng ý minh thị (KF-11 N.5) | R5: 1 | S5: C11 | T5: C11 · Sửa mũi hỏng & tái phẫu thuật ⭐⭐⭐ | U5: A · CORE 80/20 | V5: 3 | W5: =COUNTIF($B$5:$B$266,S5&"*") -> 19 | X5: =COUNTIFS($B$5:$B$266,S5&"*",$I$5:$I$266,"CORE 80/20") -> 15 | Y5: =SUMIF($B$5:$B$266,S5&"*",$L$5:$L$266) -> 1431 | Z5: =IFERROR(Y5/SUM($Y$5:$Y$19),0) -> 0.15451895 | AA5: =SUM($Z$5:Z5) -> 0.15451895 | AB5: Mỏ vàng: giá trị đơn cao nhất, đối thủ né. Trang chuyên biệt tái phẫu thuật + 8 bài tình huống hỏng + case có văn bản đồng ý.
A6: C11-02 | B6: C11 · Sửa mũi hỏng & tái phẫu thuật ⭐⭐⭐ | C6: S3 · CÂN NHẮC & NỖI SỢ (Warm→Hot) | D6: Sau khi nâng mũi hỏng bao lâu thì được sửa lại? | E6: Thời gian | F6: Hot | G6: P1 | H6: Cao | I6: CORE 80/20 | J6: =IFERROR(INDEX($U$5:$U$19,MATCH(LEFT(B6,3),$S$5:$S$19,0)),"") -> A · CORE 80/20 | K6: 2 | L6: =IF(H6="Cao",3,IF(H6="TB",2,1))*IF(F6="Hot",3,IF(F6="Warm",2,1))*(4-VALUE(RIGHT(G6,1)))*IFERROR(INDEX($V$5:$V$19,MATCH(LEFT(B6,3),$S$5:$S$19,0)),1) -> 81 | M6: nâng mũi hỏng bao lâu sửa | N6: Mốc chuẩn: tối thiểu 3–6 tháng để mô ổn định, trừ trường hợp cấp (nhiễm trùng, lộ sụn, hoại tử) phải can thiệp ngay — phân định cấp/không cấp là nội dung AI trích rất nhiều | O6: Trang con: Khắc phục mũi hỏng (pillar mũi) | P6: R9 · Nội dung dịch vụ KCB cần Giấy xác nhận nội dung QC tại Sở Y tế (KF-11) | R6: 2 | S6: C06 | T6: C06 · Nỗi sợ, rủi ro & biến chứng ⭐ | U6: A · CORE 80/20 | V6: 3 | W6: =COUNTIF($B$5:$B$266,S6&"*") -> 20 | X6: =COUNTIFS($B$5:$B$266,S6&"*",$I$5:$I$266,"CORE 80/20") -> 17 | Y6: =SUMIF($B$5:$B$266,S6&"*",$L$5:$L$266) -> 1296 | Z6: =IFERROR(Y6/SUM($Y$5:$Y$19),0) -> 0.13994169 | AA6: =SUM($Z$5:Z6) -> 0.29446064 | AB6: Gỡ rào cản lớn nhất. Trang 'rủi ro & biến chứng nói thật' có số liệu + nguồn; bài từng biến chứng. Qua Pháp chế.
A7: C11-03 | B7: C11 · Sửa mũi hỏng & tái phẫu thuật ⭐⭐⭐ | C7: S3 · CÂN NHẮC & NỖI SỢ (Warm→Hot) | D7: Mũi bị bóng đỏ đầu mũi thì có phải tháo sụn không? | E7: Xử lý | F7: Hot | G7: P1 | H7: Cao | I7: CORE 80/20 | J7: =IFERROR(INDEX($U$5:$U$19,MATCH(LEFT(B7,3),$S$5:$S$19,0)),"") -> A · CORE 80/20 | K7: 3 | L7: =IF(H7="Cao",3,IF(H7="TB",2,1))*IF(F7="Hot",3,IF(F7="Warm",2,1))*(4-VALUE(RIGHT(G7,1)))*IFERROR(INDEX($V$5:$V$19,MATCH(LEFT(B7,3),$S$5:$S$19,0)),1) -> 81 | M7: mũi bị bóng đỏ | N7: Phân tầng xử lý theo mức độ: hạ độ cao sụn, thay vật liệu mềm hơn, ghép mô đệm, hoặc tháo và chờ hồi phục | O7: Trang con: Khắc phục mũi hỏng (pillar mũi) | P7: R9 · Nội dung dịch vụ KCB cần Giấy xác nhận nội dung QC tại Sở Y tế (KF-11) | R7: 3 | S7: C07 | T7: C07 · Chi phí & bảng giá ⭐ | U7: A · CORE 80/20 | V7: 3 | W7: =COUNTIF($B$5:$B$266,S7&"*") -> 16 | X7: =COUNTIFS($B$5:$B$266,S7&"*",$I$5:$I$266,"CORE 80/20") -> 11 | Y7: =SUMIF($B$5:$B$266,S7&"*",$L$5:$L$266) -> 1131 | Z7: =IFERROR(Y7/SUM($Y$5:$Y$19),0) -> 0.12212504 | AA7: =SUM($Z$5:Z7) -> 0.41658568 | AB7: Đòn rẻ & nhanh nhất: toàn ngành giấu giá. Trang bảng giá min–max, bóc tách cấu phần, ngày cập nhật.
A8: C11-04 | B8: C11 · Sửa mũi hỏng & tái phẫu thuật ⭐⭐⭐ | C8: S3 · CÂN NHẮC & NỖI SỢ (Warm→Hot) | D8: Sửa mũi hỏng lần 2, lần 3 có được không, có giới hạn số lần không? | E8: Điều kiện | F8: Hot | G8: P1 | H8: Cao | I8: CORE 80/20 | J8: =IFERROR(INDEX($U$5:$U$19,MATCH(LEFT(B8,3),$S$5:$S$19,0)),"") -> A · CORE 80/20 | K8: 4 | L8: =IF(H8="Cao",3,IF(H8="TB",2,1))*IF(F8="Hot",3,IF(F8="Warm",2,1))*(4-VALUE(RIGHT(G8,1)))*IFERROR(INDEX($V$5:$V$19,MATCH(LEFT(B8,3),$S$5:$S$19,0)),1) -> 81 | M8: sửa mũi nhiều lần | N8: Không có giới hạn cứng nhưng mỗi lần khó hơn do sẹo và thiếu vật liệu tự thân; giải thích vì sao lần sửa đầu tiên nên làm đúng ngay | O8: Trang con: Khắc phục mũi hỏng (pillar mũi) | P8: R1 · Không cam kết 100%/vĩnh viễn/không biến chứng (KF-11 NT.3) | R8: 4 | S8: C08 | T8: C08 · Chọn cơ sở & bác sĩ ⭐⭐ | U8: A · CORE 80/20 | V8: 2 | W8: =COUNTIF($B$5:$B$266,S8&"*") -> 18 | X8: =COUNTIFS($B$5:$B$266,S8&"*",$I$5:$I$266,"CORE 80/20") -> 15 | Y8: =SUMIF($B$5:$B$266,S8&"*",$L$5:$L$266) -> 918 | Z8: =IFERROR(Y8/SUM($Y$5:$Y$19),0) -> 0.099125364 | AA8: =SUM($Z$5:Z8) -> 0.51571105 | AB8: Nơi AI thay hành vi hỏi hội nhóm. Trang local chuẩn NAP + checklist 12 câu hỏi mang đi tư vấn + hướng dẫn tự tra giấy phép.
A9: C11-05 | B9: C11 · Sửa mũi hỏng & tái phẫu thuật ⭐⭐⭐ | C9: S3 · CÂN NHẮC & NỖI SỢ (Warm→Hot) | D9: Tháo sụn mũi ra thì mũi có về được như ban đầu không? | E9: Phản đối | F9: Hot | G9: P1 | H9: Cao | I9: CORE 80/20 | J9: =IFERROR(INDEX($U$5:$U$19,MATCH(LEFT(B9,3),$S$5:$S$19,0)),"") -> A · CORE 80/20 | K9: 5 | L9: =IF(H9="Cao",3,IF(H9="TB",2,1))*IF(F9="Hot",3,IF(F9="Warm",2,1))*(4-VALUE(RIGHT(G9,1)))*IFERROR(INDEX($V$5:$V$19,MATCH(LEFT(B9,3),$S$5:$S$19,0)),1) -> 81 | M9: tháo sụn mũi | N9: Trả lời trung thực: gần giống nhưng không y hệt; mô đã co và da đã giãn; thời gian ổn định sau tháo 3–6 tháng | O9: Trang con: Khắc phục mũi hỏng (pillar mũi) | P9: R1 · Không cam kết 100%/vĩnh viễn/không biến chứng (KF-11 NT.3) | R9: 5 | S9: C14 | T9: C14 · Thực thể thương hiệu & bác sĩ (GEO Entity) ⭐⭐ | U9: A · CORE 80/20 | V9: 2 | W9: =COUNTIF($B$5:$B$266,S9&"*") -> 16 | X9: =COUNTIFS($B$5:$B$266,S9&"*",$I$5:$I$266,"CORE 80/20") -> 12 | Y9: =SUMIF($B$5:$B$266,S9&"*",$L$5:$L$266) -> 760 | Z9: =IFERROR(Y9/SUM($Y$5:$Y$19),0) -> 0.082064572 | AA9: =SUM($Z$5:Z9) -> 0.59777562 | AB9: Điều kiện cần để AI quy công về Kangnam: trang thực thể + hồ sơ bác sĩ (ProfilePage, IndividualPhysician, sameAs).
A10: C11-06 | B10: C11 · Sửa mũi hỏng & tái phẫu thuật ⭐⭐⭐ | C10: S3 · CÂN NHẮC & NỖI SỢ (Warm→Hot) | D10: Mũi bị lộ sóng thấy rõ đường viền sụn thì khắc phục thế nào? | E10: Xử lý | F10: Hot | G10: P1 | H10: Cao | I10: CORE 80/20 | J10: =IFERROR(INDEX($U$5:$U$19,MATCH(LEFT(B10,3),$S$5:$S$19,0)),"") -> A · CORE 80/20 | K10: 6 | L10: =IF(H10="Cao",3,IF(H10="TB",2,1))*IF(F10="Hot",3,IF(F10="Warm",2,1))*(4-VALUE(RIGHT(G10,1)))*IFERROR(INDEX($V$5:$V$19,MATCH(LEFT(B10,3),$S$5:$S$19,0)),1) -> 81 | M10: mũi bị lộ sóng | N10: Giải pháp: thay sụn mềm hơn/thấp hơn + ghép lớp đệm mô mềm; nêu rõ da mỏng là yếu tố cần xử lý gốc | O10: Trang con: Khắc phục mũi hỏng (pillar mũi) | P10: R9 · Nội dung dịch vụ KCB cần Giấy xác nhận nội dung QC tại Sở Y tế (KF-11) | R10: 6 | S10: C09 | T10: C09 · Quy trình, chuẩn bị & điều kiện sức khỏe | U10: B · Đòn bẩy chuyển đổi | V10: 2 | W10: =COUNTIF($B$5:$B$266,S10&"*") -> 17 | X10: =COUNTIFS($B$5:$B$266,S10&"*",$I$5:$I$266,"CORE 80/20") -> 0 | Y10: =SUMIF($B$5:$B$266,S10&"*",$L$5:$L$266) -> 672 | Z10: =IFERROR(Y10/SUM($Y$5:$Y$19),0) -> 0.072562358 | AA10: =SUM($Z$5:Z10) -> 0.67033798 | AB10: Giảm hủy lịch, tăng show-up: quy trình 8 bước có mốc + điều kiện sức khỏe + checklist chuẩn bị.
A11: C11-07 | B11: C11 · Sửa mũi hỏng & tái phẫu thuật ⭐⭐⭐ | C11: S3 · CÂN NHẮC & NỖI SỢ (Warm→Hot) | D11: Mũi bị nhiễm trùng sau nâng đã tháo sụn, giờ muốn làm lại thì chờ bao lâu? | E11: Thời gian | F11: Hot | G11: P1 | H11: Cao | I11: CORE 80/20 | J11: =IFERROR(INDEX($U$5:$U$19,MATCH(LEFT(B11,3),$S$5:$S$19,0)),"") -> A · CORE 80/20 | K11: 7 | L11: =IF(H11="Cao",3,IF(H11="TB",2,1))*IF(F11="Hot",3,IF(F11="Warm",2,1))*(4-VALUE(RIGHT(G11,1)))*IFERROR(INDEX($V$5:$V$19,MATCH(LEFT(B11,3),$S$5:$S$19,0)),1) -> 81 | M11: tháo sụn bao lâu nâng lại | N11: Chờ tối thiểu 6 tháng sau khi hết nhiễm trùng hoàn toàn; cần cấy dịch xác định vi khuẩn trước khi tái phẫu thuật | O11: Trang con: Khắc phục mũi hỏng (pillar mũi) | P11: R9 · Nội dung dịch vụ KCB cần Giấy xác nhận nội dung QC tại Sở Y tế (KF-11) | R11: 7 | S11: C04 | T11: C04 · Chất liệu sụn & vật liệu | U11: B · Đòn bẩy chuyển đổi | V11: 2 | W11: =COUNTIF($B$5:$B$266,S11&"*") -> 18 | X11: =COUNTIFS($B$5:$B$266,S11&"*",$I$5:$I$266,"CORE 80/20") -> 0 | Y11: =SUMIF($B$5:$B$266,S11&"*",$L$5:$L$266) -> 580 | Z11: =IFERROR(Y11/SUM($Y$5:$Y$19),0) -> 0.062628226 | AA11: =SUM($Z$5:Z11) -> 0.7329662 | AB11: Chứng minh chuyên môn: bài vật liệu + 'cách kiểm tra sụn thật/giả' (tem, hộp, số lưu hành).
A12: C11-08 | B12: C11 · Sửa mũi hỏng & tái phẫu thuật ⭐⭐⭐ | C12: S3 · CÂN NHẮC & NỖI SỢ (Warm→Hot) | D12: Nâng mũi bị co rút (mũi ngắn lại, hếch lên) thì sửa được không? | E12: Xử lý | F12: Hot | G12: P1 | H12: Cao | I12: CORE 80/20 | J12: =IFERROR(INDEX($U$5:$U$19,MATCH(LEFT(B12,3),$S$5:$S$19,0)),"") -> A · CORE 80/20 | K12: 8 | L12: =IF(H12="Cao",3,IF(H12="TB",2,1))*IF(F12="Hot",3,IF(F12="Warm",2,1))*(4-VALUE(RIGHT(G12,1)))*IFERROR(INDEX($V$5:$V$19,MATCH(LEFT(B12,3),$S$5:$S$19,0)),1) -> 81 | M12: mũi bị co rút | N12: Đây là ca khó nhất của tái phẫu thuật; giải pháp kéo dài bằng sụn sườn + giải phóng mô sẹo; nêu thật mức độ cải thiện có giới hạn | O12: Trang con: Khắc phục mũi hỏng (pillar mũi) | P12: R1 · Không cam kết 100%/vĩnh viễn/không biến chứng (KF-11 NT.3) | R12: 8 | S12: C05 | T12: C05 · Không phẫu thuật: filler & chỉ nâng mũi | U12: B · Đòn bẩy chuyển đổi | V12: 2 | W12: =COUNTIF($B$5:$B$266,S12&"*") -> 16 | X12: =COUNTIFS($B$5:$B$266,S12&"*",$I$5:$I$266,"CORE 80/20") -> 0 | Y12: =SUMIF($B$5:$B$266,S12&"*",$L$5:$L$266) -> 562 | Z12: =IFERROR(Y12/SUM($Y$5:$Y$19),0) -> 0.060684591 | AA12: =SUM($Z$5:Z12) -> 0.79365079 | AB12: Cầu nối chi phí thấp → phẫu thuật: bài 'đã tiêm filler giờ muốn nâng mũi'.
A13: C11-09 | B13: C11 · Sửa mũi hỏng & tái phẫu thuật ⭐⭐⭐ | C13: S3 · CÂN NHẮC & NỖI SỢ (Warm→Hot) | D13: Mũi sau nâng bị lệch sang một bên thì sửa lại có khó không? | E13: Xử lý | F13: Hot | G13: P1 | H13: Cao | I13: CORE 80/20 | J13: =IFERROR(INDEX($U$5:$U$19,MATCH(LEFT(B13,3),$S$5:$S$19,0)),"") -> A · CORE 80/20 | K13: 9 | L13: =IF(H13="Cao",3,IF(H13="TB",2,1))*IF(F13="Hot",3,IF(F13="Warm",2,1))*(4-VALUE(RIGHT(G13,1)))*IFERROR(INDEX($V$5:$V$19,MATCH(LEFT(B13,3),$S$5:$S$19,0)),1) -> 81 | M13: sửa mũi bị lệch | N13: Phân biệt lệch do sụn, do trục xương, do bao xơ co kéo; mỗi nguyên nhân một hướng xử lý | O13: Trang con: Khắc phục mũi hỏng (pillar mũi) | P13: R9 · Nội dung dịch vụ KCB cần Giấy xác nhận nội dung QC tại Sở Y tế (KF-11) | R13: 9 | S13: C12 | T13: C12 · Chức năng mũi & y khoa (E-E-A-T) | U13: C · Uy tín & giữ chân | V13: 2 | W13: =COUNTIF($B$5:$B$266,S13&"*") -> 16 | X13: =COUNTIFS($B$5:$B$266,S13&"*",$I$5:$I$266,"CORE 80/20") -> 0 | Y13: =SUMIF($B$5:$B$266,S13&"*",$L$5:$L$266) -> 426 | Z13: =IFERROR(Y13/SUM($Y$5:$Y$19),0) -> 0.045999352 | AA13: =SUM($Z$5:Z13) -> 0.83965015 | AB13: Trục uy tín y khoa (E-E-A-T): 6 bài chức năng mũi/vách ngăn có bác sĩ thẩm định.
A14: C11-10 | B14: C11 · Sửa mũi hỏng & tái phẫu thuật ⭐⭐⭐ | C14: S3 · CÂN NHẮC & NỖI SỢ (Warm→Hot) | D14: Đầu mũi bị mỏng và sắp thủng thì phải làm gì ngay? | E14: Cấp cứu | F14: Hot | G14: P1 | H14: Cao | I14: CORE 80/20 | J14: =IFERROR(INDEX($U$5:$U$19,MATCH(LEFT(B14,3),$S$5:$S$19,0)),"") -> A · CORE 80/20 | K14: 10 | L14: =IF(H14="Cao",3,IF(H14="TB",2,1))*IF(F14="Hot",3,IF(F14="Warm",2,1))*(4-VALUE(RIGHT(G14,1)))*IFERROR(INDEX($V$5:$V$19,MATCH(LEFT(B14,3),$S$5:$S$19,0)),1) -> 81 | M14: đầu mũi bị mỏng | N14: Đây là tình huống KHẨN: hướng dẫn liên hệ ngay, không chờ; nguy cơ lộ sụn và nhiễm trùng lan | O14: Trang con: Khắc phục mũi hỏng (pillar mũi) | P14: R9 · Nội dung dịch vụ KCB cần Giấy xác nhận nội dung QC tại Sở Y tế (KF-11) | R14: 10 | S14: C13 | T14: C13 · Nhóm khách hàng đặc thù | U14: B · Đòn bẩy chuyển đổi | V14: 2 | W14: =COUNTIF($B$5:$B$266,S14&"*") -> 15 | X14: =COUNTIFS($B$5:$B$266,S14&"*",$I$5:$I$266,"CORE 80/20") -> 0 | Y14: =SUMIF($B$5:$B$266,S14&"*",$L$5:$L$266) -> 420 | Z14: =IFERROR(Y14/SUM($Y$5:$Y$19),0) -> 0.045351474 | AA14: =SUM($Z$5:Z14) -> 0.88500162 | AB14: Khớp truy vấn dài có ngữ cảnh: 5 bài phân khúc (nam, 40+, da mỏng, da dày, khách tỉnh).
A15: C11-11 | B15: C11 · Sửa mũi hỏng & tái phẫu thuật ⭐⭐⭐ | C15: S3 · CÂN NHẮC & NỖI SỢ (Warm→Hot) | D15: Chi phí sửa mũi hỏng khoảng bao nhiêu? | E15: Chi phí | F15: Hot | G15: P1 | H15: Cao | I15: CORE 80/20 | J15: =IFERROR(INDEX($U$5:$U$19,MATCH(LEFT(B15,3),$S$5:$S$19,0)),"") -> A · CORE 80/20 | K15: 11 | L15: =IF(H15="Cao",3,IF(H15="TB",2,1))*IF(F15="Hot",3,IF(F15="Warm",2,1))*(4-VALUE(RIGHT(G15,1)))*IFERROR(INDEX($V$5:$V$19,MATCH(LEFT(B15,3),$S$5:$S$19,0)),1) -> 81 | M15: giá sửa mũi hỏng | N15: Khoảng giá theo mức độ (tháo đơn thuần / thay sụn / tái cấu trúc toàn bộ bằng sụn sườn) — công khai giá cụm này gần như không cơ sở nào làm | O15: /bang-gia/#tham-my-mui | P15: R9 · Nội dung dịch vụ KCB cần Giấy xác nhận nội dung QC tại Sở Y tế (KF-11) | R15: 11 | S15: C03 | T15: C03 · Phương pháp & công nghệ nâng mũi | U15: B · Đòn bẩy chuyển đổi | V15: 1 | W15: =COUNTIF($B$5:$B$266,S15&"*") -> 20 | X15: =COUNTIFS($B$5:$B$266,S15&"*",$I$5:$I$266,"CORE 80/20") -> 0 | Y15: =SUMIF($B$5:$B$266,S15&"*",$L$5:$L$266) -> 299 | Z15: =IFERROR(Y15/SUM($Y$5:$Y$19),0) -> 0.03228593 | AA15: =SUM($Z$5:Z15) -> 0.91728755 | AB15: Nơi AI trả lời nhiều nhất nhưng cạnh tranh đông: 1 pillar bảng so sánh 5 phương pháp, nêu cả nhược điểm.
A16: C11-12 | B16: C11 · Sửa mũi hỏng & tái phẫu thuật ⭐⭐⭐ | C16: S3 · CÂN NHẮC & NỖI SỢ (Warm→Hot) | D16: Sửa mũi hỏng ở nơi khác thì Kangnam có nhận không? | E16: Quy trình | F16: Hot | G16: P1 | H16: Cao | I16: CORE 80/20 | J16: =IFERROR(INDEX($U$5:$U$19,MATCH(LEFT(B16,3),$S$5:$S$19,0)),"") -> A · CORE 80/20 | K16: 12 | L16: =IF(H16="Cao",3,IF(H16="TB",2,1))*IF(F16="Hot",3,IF(F16="Warm",2,1))*(4-VALUE(RIGHT(G16,1)))*IFERROR(INDEX($V$5:$V$19,MATCH(LEFT(B16,3),$S$5:$S$19,0)),1) -> 81 | M16: thẩm mỹ kangnam sửa mũi hỏng | N16: Khẳng định có tiếp nhận + quy trình đánh giá lại + tinh thần không phán xét nơi cũ — thái độ này quyết định chuyển đổi cụm giá trị cao nhất | O16: Trang con: Khắc phục mũi hỏng (pillar mũi) | P16: R6 · KHÔNG so sánh trực tiếp/nêu tên đối thủ — chỉ đưa bộ tiêu chí khách quan | R16: 12 | S16: C10 | T16: C10 · Hậu phẫu & chăm sóc ⭐ | U16: C · Uy tín & giữ chân | V16: 1 | W16: =COUNTIF($B$5:$B$266,S16&"*") -> 20 | X16: =COUNTIFS($B$5:$B$266,S16&"*",$I$5:$I$266,"CORE 80/20") -> 0 | Y16: =SUMIF($B$5:$B$266,S16&"*",$L$5:$L$266) -> 231 | Z16: =IFERROR(Y16/SUM($Y$5:$Y$19),0) -> 0.024943311 | AA16: =SUM($Z$5:Z16) -> 0.94223086 | AB16: Không tạo lead mới nhưng neo thực thể + giảm biến chứng do chăm sai: cẩm nang hậu phẫu theo mốc, nhúng Zalo OA.
... A19: C11-18 | B19: C11 · Sửa mũi hỏng & tái phẫu thuật ⭐⭐⭐ | C19: S3 · CÂN NHẮC & NỖI SỢ (Warm→Hot) | D19: Sửa mũi hỏng cần dùng sụn sườn hay sụn tai là đủ? | E19: So sánh | F19: Hot | G19: P1 | H19: Cao | I19: CORE 80/20 | J19: =IFERROR(INDEX($U$5:$U$19,MATCH(LEFT(B19,3),$S$5:$S$19,0)),"") -> A · CORE 80/20 | K19: 15 | L19: =IF(H19="Cao",3,IF(H19="TB",2,1))*IF(F19="Hot",3,IF(F19="Warm",2,1))*(4-VALUE(RIGHT(G19,1)))*IFERROR(INDEX($V$5:$V$19,MATCH(LEFT(B19,3),$S$5:$S$19,0)),1) -> 81 | M19: sửa mũi bằng sụn sườn | N19: Tiêu chí chọn theo lượng sụn cần và số lần đã mổ; đa số ca tái phẫu thuật phức tạp cần sụn sườn | O19: /kien-thuc/mui/nang-mui-cau-truc/ | P19: R9 · Nội dung dịch vụ KCB cần Giấy xác nhận nội dung QC tại Sở Y tế (KF-11) | R19: 15 | S19: C02 | T19: C02 · Nhân tướng & phong thủy mũi (đặc thù VN) | U19: D · Cửa vào rộng | V19: 1 | W19: =COUNTIF($B$5:$B$266,S19&"*") -> 18 | X19: =COUNTIFS($B$5:$B$266,S19&"*",$I$5:$I$266,"CORE 80/20") -> 0 | Y19: =SUMIF($B$5:$B$266,S19&"*",$L$5:$L$266) -> 134 | Z19: =IFERROR(Y19/SUM($Y$5:$Y$19),0) -> 0.01446928 | AA19: =SUM($Z$5:Z19) -> 1 | AB19: Traffic lớn, đặc thù VN: 1 bài tổng hợp quan niệm nhân tướng + FAQ, dẫn mềm sang giải pháp.
A20: C08-01 | B20: C08 · Chọn cơ sở & bác sĩ ⭐⭐ | C20: S3 · CÂN NHẮC & NỖI SỢ (Warm→Hot) | D20: Nâng mũi ở đâu uy tín và an toàn tại Hà Nội? | E20: Local | F20: Hot | G20: P1 | H20: Cao | I20: CORE 80/20 | J20: =IFERROR(INDEX($U$5:$U$19,MATCH(LEFT(B20,3),$S$5:$S$19,0)),"") -> A · CORE 80/20 | K20: 16 | L20: =IF(H20="Cao",3,IF(H20="TB",2,1))*IF(F20="Hot",3,IF(F20="Warm",2,1))*(4-VALUE(RIGHT(G20,1)))*IFERROR(INDEX($V$5:$V$19,MATCH(LEFT(B20,3),$S$5:$S$19,0)),1) -> 54 | M20: nâng mũi uy tín hà nội | N20: Trang local có: địa chỉ NAP chuẩn, giấy phép, danh sách bác sĩ đúng chuyên khoa, ảnh thực tế cơ sở, schema MedicalClinic + IndividualPhysician | O20: /dich-vu/nang-mui/nang-mui-o-dau-dep/ | P20: R9 · Nội dung dịch vụ KCB cần Giấy xác nhận nội dung QC tại Sở Y tế (KF-11) | T20: TỔNG | W20: =SUM(W5:W19) -> 262 | X20: =SUM(X5:X19) -> 70 | Y20: =SUM(Y5:Y19) -> 9261
A21: C08-02 | B21: C08 · Chọn cơ sở & bác sĩ ⭐⭐ | C21: S3 · CÂN NHẮC & NỖI SỢ (Warm→Hot) | D21: Làm sao để biết một cơ sở thẩm mỹ có được cấp phép phẫu thuật mũi hay không? | E21: Kiểm chứng | F21: Hot | G21: P1 | H21: Cao | I21: CORE 80/20 | J21: =IFERROR(INDEX($U$5:$U$19,MATCH(LEFT(B21,3),$S$5:$S$19,0)),"") -> A · CORE 80/20 | K21: 17 | L21: =IF(H21="Cao",3,IF(H21="TB",2,1))*IF(F21="Hot",3,IF(F21="Warm",2,1))*(4-VALUE(RIGHT(G21,1)))*IFERROR(INDEX($V$5:$V$19,MATCH(LEFT(B21,3),$S$5:$S$19,0)),1) -> 54 | M21: tra cứu giấy phép thẩm mỹ | N21: Hướng dẫn từng bước tra cứu trên cổng thông tin Sở Y tế + đọc phạm vi chuyên môn trong giấy phép; nội dung 'dạy khách tự kiểm tra' tạo uy tín cực mạnh | O21: /chuyen-khoa/chuyen-khoa-tham-my-mui/ | P21: R9 · Nội dung dịch vụ KCB cần Giấy xác nhận nội dung QC tại Sở Y tế (KF-11)
A22: C08-03 | B22: C08 · Chọn cơ sở & bác sĩ ⭐⭐ | C22: S3 · CÂN NHẮC & NỖI SỢ (Warm→Hot) | D22: Tiêu chí nào để chọn bác sĩ nâng mũi giỏi? | E22: Kiểm chứng | F22: Hot | G22: P1 | H22: Cao | I22: CORE 80/20 | J22: =IFERROR(INDEX($U$5:$U$19,MATCH(LEFT(B22,3),$S$5:$S$19,0)),"") -> A · CORE 80/20 | K22: 18 | L22: =IF(H22="Cao",3,IF(H22="TB",2,1))*IF(F22="Hot",3,IF(F22="Warm",2,1))*(4-VALUE(RIGHT(G22,1)))*IFERROR(INDEX($V$5:$V$19,MATCH(LEFT(B22,3),$S$5:$S$19,0)),1) -> 54 | M22: chọn bác sĩ nâng mũi | N22: Bộ 7 tiêu chí kiểm chứng được: chứng chỉ hành nghề, phạm vi chuyên môn, số năm chuyên sâu mũi, case cùng dáng mũi, minh bạch rủi ro, sẵn sàng từ chối ca không phù hợp, chế độ theo dõi | O22: /doi-ngu-bac-si/ | P22: R4 · Chỉ gắn bác sĩ đúng chuyên khoa + đã đăng ký hành nghề tại cơ sở (KF-11 N.6, KF-02) | R22: TÓM TẮT THEO TẦNG — Pareto thực tế của bộ
A23: C08-04 | B23: C08 · Chọn cơ sở & bác sĩ ⭐⭐ | C23: S3 · CÂN NHẮC & NỖI SỢ (Warm→Hot) | D23: Bác sĩ nào chuyên về thẩm mỹ mũi ở Hà Nội? | E23: Thực thể | F23: Hot | G23: P1 | H23: Cao | I23: CORE 80/20 | J23: =IFERROR(INDEX($U$5:$U$19,MATCH(LEFT(B23,3),$S$5:$S$19,0)),"") -> A · CORE 80/20 | K23: 19 | L23: =IF(H23="Cao",3,IF(H23="TB",2,1))*IF(F23="Hot",3,IF(F23="Warm",2,1))*(4-VALUE(RIGHT(G23,1)))*IFERROR(INDEX($V$5:$V$19,MATCH(LEFT(B23,3),$S$5:$S$19,0)),1) -> 54 | M23: bác sĩ nâng mũi hà nội | N23: Trang hồ sơ bác sĩ đầy đủ schema ProfilePage + IndividualPhysician + practicesAt; CHỈ nêu bác sĩ đã xác minh chuyên khoa trong KF-02 | O23: /doi-ngu-bac-si/ | P23: R4 · Chỉ gắn bác sĩ đúng chuyên khoa + đã đăng ký hành nghề tại cơ sở (KF-11 N.6, KF-02) | T23: Tầng | V23: Số cụm | W23: Số TV | X23: % TV | Y23: % điểm
A24: C08-05 | B24: C08 · Chọn cơ sở & bác sĩ ⭐⭐ | C24: S3 · CÂN NHẮC & NỖI SỢ (Warm→Hot) | D24: Nên nâng mũi ở bệnh viện hay ở thẩm mỹ viện? | E24: So sánh | F24: Hot | G24: P1 | H24: Cao | I24: CORE 80/20 | J24: =IFERROR(INDEX($U$5:$U$19,MATCH(LEFT(B24,3),$S$5:$S$19,0)),"") -> A · CORE 80/20 | K24: 20 | L24: =IF(H24="Cao",3,IF(H24="TB",2,1))*IF(F24="Hot",3,IF(F24="Warm",2,1))*(4-VALUE(RIGHT(G24,1)))*IFERROR(INDEX($V$5:$V$19,MATCH(LEFT(B24,3),$S$5:$S$19,0)),1) -> 54 | M24: nâng mũi ở bệnh viện | N24: So sánh theo năng lực xử lý sự cố: phòng mổ đạt chuẩn, ekip gây mê, khả năng lưu bệnh nhân — nêu tiêu chí, không nêu tên cơ sở khác | O24: /chuyen-khoa/chuyen-khoa-tham-my-mui/ | P24: R6 · KHÔNG so sánh trực tiếp/nêu tên đối thủ — chỉ đưa bộ tiêu chí khách quan | T24: A · CORE 80/20 | V24: =COUNTIF($U$5:$U$19,T24) -> 5 | W24: =COUNTIF($J$5:$J$266,T24) -> 89 | X24: =IFERROR(W24/COUNTA($A$5:$A$266),0) -> 0.33969466 | Y24: =IFERROR(SUMIF($J$5:$J$266,T24,$L$5:$L$266)/SUM($L$5:$L$266),0) -> 0.59777562
A25: C08-06 | B25: C08 · Chọn cơ sở & bác sĩ ⭐⭐ | C25: S3 · CÂN NHẮC & NỖI SỢ (Warm→Hot) | D25: Kangnam có phải là bệnh viện thẩm mỹ được cấp phép không? | E25: Thực thể | F25: Hot | G25: P1 | H25: Cao | I25: CORE 80/20 | J25: =IFERROR(INDEX($U$5:$U$19,MATCH(LEFT(B25,3),$S$5:$S$19,0)),"") -> A · CORE 80/20 | K25: 21 | L25: =IF(H25="Cao",3,IF(H25="TB",2,1))*IF(F25="Hot",3,IF(F25="Warm",2,1))*(4-VALUE(RIGHT(G25,1)))*IFERROR(INDEX($V$5:$V$19,MATCH(LEFT(B25,3),$S$5:$S$19,0)),1) -> 54 | M25: thẩm mỹ kangnam cấp phép | N25: Trang thông tin pháp nhân chuẩn: tên pháp nhân, số giấy phép, phạm vi chuyên môn, địa chỉ từng chi nhánh — neo thực thể cho AI | O25: /chuyen-khoa/chuyen-khoa-tham-my-mui/ | P25: R3 · Ghi ĐÚNG pháp nhân đứng tên từng chi nhánh (KF-11 N.3 — điểm nóng nhất) | T25: B · Đòn bẩy chuyển đổi | V25: =COUNTIF($U$5:$U$19,T25) -> 5 | W25: =COUNTIF($J$5:$J$266,T25) -> 86 | X25: =IFERROR(W25/COUNTA($A$5:$A$266),0) -> 0.32824427 | Y25: =IFERROR(SUMIF($J$5:$J$266,T25,$L$5:$L$266)/SUM($L$5:$L$266),0) -> 0.27351258
A26: C08-07 | B26: C08 · Chọn cơ sở & bác sĩ ⭐⭐ | C26: S3 · CÂN NHẮC & NỖI SỢ (Warm→Hot) | D26: Review nâng mũi ở Kangnam có thật không? | E26: Bằng chứng | F26: Hot | G26: P1 | H26: Cao | I26: CORE 80/20 | J26: =IFERROR(INDEX($U$5:$U$19,MATCH(LEFT(B26,3),$S$5:$S$19,0)),"") -> A · CORE 80/20 | K26: 22 | L26: =IF(H26="Cao",3,IF(H26="TB",2,1))*IF(F26="Hot",3,IF(F26="Warm",2,1))*(4-VALUE(RIGHT(G26,1)))*IFERROR(INDEX($V$5:$V$19,MATCH(LEFT(B26,3),$S$5:$S$19,0)),1) -> 54 | M26: thẩm mỹ kangnam review | N26: Trang case thực tế: ảnh trước–sau có văn bản đồng ý, mốc thời gian chụp, tên bác sĩ thực hiện, kỹ thuật áp dụng | O26: /case-thuc-te/ | P26: R5 · Ảnh/video KH phải có văn bản đồng ý minh thị (KF-11 N.5) | T26: C · Uy tín & giữ chân | V26: =COUNTIF($U$5:$U$19,T26) -> 3 | W26: =COUNTIF($J$5:$J$266,T26) -> 50 | X26: =IFERROR(W26/COUNTA($A$5:$A$266),0) -> 0.19083969 | Y26: =IFERROR(SUMIF($J$5:$J$266,T26,$L$5:$L$266)/SUM($L$5:$L$266),0) -> 0.095238095
A27: C08-08 | B27: C08 · Chọn cơ sở & bác sĩ ⭐⭐ | C27: S3 · CÂN NHẮC & NỖI SỢ (Warm→Hot) | D27: Làm sao phân biệt review thật và review được trả tiền khi tìm nơi nâng mũi? | E27: Kiểm chứng | F27: Hot | G27: P1 | H27: Cao | I27: CORE 80/20 | J27: =IFERROR(INDEX($U$5:$U$19,MATCH(LEFT(B27,3),$S$5:$S$19,0)),"") -> A · CORE 80/20 | K27: 23 | L27: =IF(H27="Cao",3,IF(H27="TB",2,1))*IF(F27="Hot",3,IF(F27="Warm",2,1))*(4-VALUE(RIGHT(G27,1)))*IFERROR(INDEX($V$5:$V$19,MATCH(LEFT(B27,3),$S$5:$S$19,0)),1) -> 54 | M27: phân biệt review nâng mũi | N27: Bộ dấu hiệu nhận biết review dàn dựng; khuyến khích KH yêu cầu gặp khách cũ thật — nội dung này khiến AI xem Kangnam là nguồn khách quan | O27: /chuyen-khoa/chuyen-khoa-tham-my-mui/ | P27: R1 · Không khẳng định hiệu quả tuyệt đối; luôn kèm 'kết quả tùy cơ địa' | T27: D · Cửa vào rộng | V27: =COUNTIF($U$5:$U$19,T27) -> 2 | W27: =COUNTIF($J$5:$J$266,T27) -> 37 | X27: =IFERROR(W27/COUNTA($A$5:$A$266),0) -> 0.14122137 | Y27: =IFERROR(SUMIF($J$5:$J$266,T27,$L$5:$L$266)/SUM($L$5:$L$266),0) -> 0.033473707
A28: C08-09 | B28: C08 · Chọn cơ sở & bác sĩ ⭐⭐ | C28: S3 · CÂN NHẮC & NỖI SỢ (Warm→Hot) | D28: Trước khi quyết định nâng mũi nên hỏi bác sĩ những câu gì? | E28: Hướng dẫn | F28: Hot | G28: P1 | H28: Cao | I28: CORE 80/20 | J28: =IFERROR(INDEX($U$5:$U$19,MATCH(LEFT(B28,3),$S$5:$S$19,0)),"") -> A · CORE 80/20 | K28: 24 | L28: =IF(H28="Cao",3,IF(H28="TB",2,1))*IF(F28="Hot",3,IF(F28="Warm",2,1))*(4-VALUE(RIGHT(G28,1)))*IFERROR(INDEX($V$5:$V$19,MATCH(LEFT(B28,3),$S$5:$S$19,0)),1) -> 54 | M28: tư vấn nâng mũi hỏi gì | N28: Danh sách 12 câu hỏi in ra mang đi tư vấn (ai mổ chính, kỹ thuật gì, vật liệu gì có tem không, xử lý biến chứng ra sao...) — dạng checklist AI rất thích trích nguyên khối | O28: /chuyen-khoa/chuyen-khoa-tham-my-mui/ | P28: R9 · Nội dung dịch vụ KCB cần Giấy xác nhận nội dung QC tại Sở Y tế (KF-11) | T28: Riêng 70 truy vấn CORE 80/20 | V28: — | W28: =COUNTIF($I$5:$I$266,"CORE 80/20") -> 70 | X28: =IFERROR(W28/COUNTA($A$5:$A$266),0) -> 0.26717557 | Y28: =IFERROR(SUMIF($I$5:$I$266,"CORE 80/20",$L$5:$L$266)/SUM($L$5:$L$266),0) -> 0.51311953
A29: C08-10 | B29: C08 · Chọn cơ sở & bác sĩ ⭐⭐ | C29: S3 · CÂN NHẮC & NỖI SỢ (Warm→Hot) | D29: Có nên đi tư vấn ở nhiều nơi trước khi nâng mũi không? | E29: Hướng dẫn | F29: Hot | G29: P1 | H29: Cao | I29: CORE 80/20 | J29: =IFERROR(INDEX($U$5:$U$19,MATCH(LEFT(B29,3),$S$5:$S$19,0)),"") -> A · CORE 80/20 | K29: 25 | L29: =IF(H29="Cao",3,IF(H29="TB",2,1))*IF(F29="Hot",3,IF(F29="Warm",2,1))*(4-VALUE(RIGHT(G29,1)))*IFERROR(INDEX($V$5:$V$19,MATCH(LEFT(B29,3),$S$5:$S$19,0)),1) -> 54 | M29: tư vấn nâng mũi nhiều nơi | N29: Khuyến khích thẳng: nên đi 2–3 nơi; cách so sánh phương án tư vấn; dấu hiệu tư vấn ép chốt cần tránh — thái độ tự tin này tạo tin cậy rất mạnh | O29: /chuyen-khoa/chuyen-khoa-tham-my-mui/ | P29: R1 · Không khẳng định hiệu quả tuyệt đối; luôn kèm 'kết quả tùy cơ địa'
A30: C08-11 | B30: C08 · Chọn cơ sở & bác sĩ ⭐⭐ | C30: S3 · CÂN NHẮC & NỖI SỢ (Warm→Hot) | D30: Bác sĩ tư vấn và bác sĩ mổ có phải là một người không? | E30: Kiểm chứng | F30: Hot | G30: P1 | H30: Cao | I30: CORE 80/20 | J30: =IFERROR(INDEX($U$5:$U$19,MATCH(LEFT(B30,3),$S$5:$S$19,0)),"") -> A · CORE 80/20 | K30: 26 | L30: =IF(H30="Cao",3,IF(H30="TB",2,1))*IF(F30="Hot",3,IF(F30="Warm",2,1))*(4-VALUE(RIGHT(G30,1)))*IFERROR(INDEX($V$5:$V$19,MATCH(LEFT(B30,3),$S$5:$S$19,0)),1) -> 54 | M30: bác sĩ tư vấn nâng mũi | N30: Nêu rõ nguyên tắc bác sĩ trực tiếp thăm khám và phẫu thuật; hướng dẫn KH yêu cầu ghi tên bác sĩ mổ vào hồ sơ | O30: /doi-ngu-bac-si/ | P30: R4 · Chỉ gắn bác sĩ đúng chuyên khoa + đã đăng ký hành nghề tại cơ sở (KF-11 N.6, KF-02) | R30: ĐỌC ĐÚNG CON SỐ 80/20: bộ này đã được chọn lọc (72% truy vấn gắn giá trị 'Cao'), nên điểm phân bố phẳng hơn quy luật 80/20 cổ điển — với trọng số hiện tại, nhóm CORE (27% bộ) chiếm khoảng một nửa điểm, và phải ~50% bộ mới đạt 80% điểm. 80/20 thật nằm ở DOANH THU: hiệu chỉnh cột Giá trị DT và Cơ hội GEO bằng số Caresoft (doanh thu & tỉ lệ chốt theo nhu cầu: sửa mũi hỏng vs nâng mũi mới, lead từ bài giá…) sau 1–2 tháng, rồi để bảng tự xếp lại. Quyết định giữ nguyên: Tầng A làm trước vì vừa giá trị cao, vừa sát chuyển đổi, vừa là khoảng trống đối thủ bỏ lại.
A31: C08-13 | B31: C08 · Chọn cơ sở & bác sĩ ⭐⭐ | C31: S3 · CÂN NHẮC & NỖI SỢ (Warm→Hot) | D31: Nâng mũi ở Kangnam chi nhánh nào tốt nhất? | E31: Local | F31: Hot | G31: P1 | H31: Cao | I31: CORE 80/20 | J31: =IFERROR(INDEX($U$5:$U$19,MATCH(LEFT(B31,3),$S$5:$S$19,0)),"") -> A · CORE 80/20 | K31: 27 | L31: =IF(H31="Cao",3,IF(H31="TB",2,1))*IF(F31="Hot",3,IF(F31="Warm",2,1))*(4-VALUE(RIGHT(G31,1)))*IFERROR(INDEX($V$5:$V$19,MATCH(LEFT(B31,3),$S$5:$S$19,0)),1) -> 54 | M31: thẩm mỹ kangnam chi nhánh | N31: Trang hệ thống chi nhánh: từng chi nhánh có pháp nhân, giấy phép, dịch vụ được cấp phép, bác sĩ phụ trách — tránh nói chung chung | O31: /dich-vu/nang-mui/nang-mui-o-dau-dep/ | P31: R3 · Mỗi chi nhánh gắn ĐÚNG pháp nhân và phạm vi cấp phép (KF-11 N.3)
A32: C08-14 | B32: C08 · Chọn cơ sở & bác sĩ ⭐⭐ | C32: S3 · CÂN NHẮC & NỖI SỢ (Warm→Hot) | D32: Bệnh viện thẩm mỹ nào ở Hà Nội có phòng mổ đạt chuẩn? | E32: Kiểm chứng | F32: Hot | G32: P1 | H32: Cao | I32: CORE 80/20 | J32: =IFERROR(INDEX($U$5:$U$19,MATCH(LEFT(B32,3),$S$5:$S$19,0)),"") -> A · CORE 80/20 | K32: 28 | L32: =IF(H32="Cao",3,IF(H32="TB",2,1))*IF(F32="Hot",3,IF(F32="Warm",2,1))*(4-VALUE(RIGHT(G32,1)))*IFERROR(INDEX($V$5:$V$19,MATCH(LEFT(B32,3),$S$5:$S$19,0)),1) -> 54 | M32: bệnh viện thẩm mỹ hà nội | N32: Nội dung giải thích tiêu chuẩn phòng mổ và cách khách tự kiểm chứng (yêu cầu tham quan); kèm minh chứng của Kangnam | O32: /dich-vu/nang-mui/nang-mui-o-dau-dep/ | P32: R9 · Nội dung dịch vụ KCB cần Giấy xác nhận nội dung QC tại Sở Y tế (KF-11)
A33: C08-15 | B33: C08 · Chọn cơ sở & bác sĩ ⭐⭐ | C33: S3 · CÂN NHẮC & NỖI SỢ (Warm→Hot) | D33: Nâng mũi có cần đặt lịch trước không, quy trình đặt lịch thế nào? | E33: Quy trình | F33: Hot | G33: P1 | H33: Cao | I33: CORE 80/20 | J33: =IFERROR(INDEX($U$5:$U$19,MATCH(LEFT(B33,3),$S$5:$S$19,0)),"") -> A · CORE 80/20 | K33: 29 | L33: =IF(H33="Cao",3,IF(H33="TB",2,1))*IF(F33="Hot",3,IF(F33="Warm",2,1))*(4-VALUE(RIGHT(G33,1)))*IFERROR(INDEX($V$5:$V$19,MATCH(LEFT(B33,3),$S$5:$S$19,0)),1) -> 54 | M33: đặt lịch nâng mũi | N33: Quy trình đặt lịch rõ ràng có số hotline/Zalo OA + thời gian phản hồi cam kết; CTA rõ để AI trích được đường dẫn hành động | O33: /dich-vu/nang-mui/nang-mui-o-dau-dep/ | P33: R9 · Nội dung dịch vụ KCB cần Giấy xác nhận nội dung QC tại Sở Y tế (KF-11)
A34: C08-18 | B34: C08 · Chọn cơ sở & bác sĩ ⭐⭐ | C34: S3 · CÂN NHẮC & NỖI SỢ (Warm→Hot) | D34: Nâng mũi ở đâu có chính sách bảo hành và theo dõi sau mổ rõ ràng? | E34: Kiểm chứng | F34: Hot | G34: P1 | H34: Cao | I34: CORE 80/20 | J34: =IFERROR(INDEX($U$5:$U$19,MATCH(LEFT(B34,3),$S$5:$S$19,0)),"") -> A · CORE 80/20 | K34: 30 | L34: =IF(H34="Cao",3,IF(H34="TB",2,1))*IF(F34="Hot",3,IF(F34="Warm",2,1))*(4-VALUE(RIGHT(G34,1)))*IFERROR(INDEX($V$5:$V$19,MATCH(LEFT(B34,3),$S$5:$S$19,0)),1) -> 54 | M34: nâng mũi bảo hành | N34: Trình bày lịch tái khám cụ thể theo mốc (ngày 3, 7, 30, 90, 180) và chính sách xử lý khi có vấn đề — thay từ 'bảo hành' bằng 'chế độ theo dõi và chỉnh sửa' | O34: /chuyen-khoa/chuyen-khoa-tham-my-mui/ | P34: R1 · Tránh từ 'bảo hành trọn đời'/'cam kết đẹp 100%' (KF-11 NT.3)
A35: C14-01 | B35: C14 · Thực thể thương hiệu & bác sĩ (GEO Entity) ⭐⭐ | C35: S3 · CÂN NHẮC & NỖI SỢ (Warm→Hot) | D35: Bệnh viện Thẩm mỹ Kangnam là bệnh viện nào, ở đâu, thuộc pháp nhân nào? | E35: Thực thể | F35: Hot | G35: P1 | H35: Cao | I35: CORE 80/20 | J35: =IFERROR(INDEX($U$5:$U$19,MATCH(LEFT(B35,3),$S$5:$S$19,0)),"") -> A · CORE 80/20 | K35: 31 | L35: =IF(H35="Cao",3,IF(H35="TB",2,1))*IF(F35="Hot",3,IF(F35="Warm",2,1))*(4-VALUE(RIGHT(G35,1)))*IFERROR(INDEX($V$5:$V$19,MATCH(LEFT(B35,3),$S$5:$S$19,0)),1) -> 54 | M35: bệnh viện thẩm mỹ kangnam | N35: Trang 'Về chúng tôi' chuẩn thực thể: tên pháp nhân đầy đủ, MST, giấy phép, năm thành lập, địa chỉ từng chi nhánh, schema Organization + sameAs | O35: /chuyen-khoa/chuyen-khoa-tham-my-mui/ | P35: R3 · Ghi ĐÚNG pháp nhân từng chi nhánh — điểm nóng KF-11 N.3
A36: C14-02 | B36: C14 · Thực thể thương hiệu & bác sĩ (GEO Entity) ⭐⭐ | C36: S3 · CÂN NHẮC & NỖI SỢ (Warm→Hot) | D36: Kangnam có bao nhiêu chi nhánh và ở những tỉnh thành nào? | E36: Thực thể | F36: Hot | G36: P1 | H36: Cao | I36: CORE 80/20 | J36: =IFERROR(INDEX($U$5:$U$19,MATCH(LEFT(B36,3),$S$5:$S$19,0)),"") -> A · CORE 80/20 | K36: 32 | L36: =IF(H36="Cao",3,IF(H36="TB",2,1))*IF(F36="Hot",3,IF(F36="Warm",2,1))*(4-VALUE(RIGHT(G36,1)))*IFERROR(INDEX($V$5:$V$19,MATCH(LEFT(B36,3),$S$5:$S$19,0)),1) -> 54 | M36: thẩm mỹ kangnam chi nhánh | N36: Bảng chi nhánh: tên, địa chỉ NAP nhất quán, số điện thoại, giờ mở cửa, dịch vụ được cấp phép tại chi nhánh đó | O36: /dich-vu/nang-mui/nang-mui-o-dau-dep/ | P36: R3 · Mỗi chi nhánh gắn đúng pháp nhân và phạm vi cấp phép
A37: C14-03 | B37: C14 · Thực thể thương hiệu & bác sĩ (GEO Entity) ⭐⭐ | C37: S3 · CÂN NHẮC & NỖI SỢ (Warm→Hot) | D37: Giám đốc chuyên môn của Kangnam là ai? | E37: Thực thể | F37: Hot | G37: P1 | H37: Cao | I37: CORE 80/20 | J37: =IFERROR(INDEX($U$5:$U$19,MATCH(LEFT(B37,3),$S$5:$S$19,0)),"") -> A · CORE 80/20 | K37: 33 | L37: =IF(H37="Cao",3,IF(H37="TB",2,1))*IF(F37="Hot",3,IF(F37="Warm",2,1))*(4-VALUE(RIGHT(G37,1)))*IFERROR(INDEX($V$5:$V$19,MATCH(LEFT(B37,3),$S$5:$S$19,0)),1) -> 54 | M37: thẩm mỹ kangnam giám đốc | N37: Hồ sơ TS.BS Võ Tiến Huy (Richard Huy) với schema ProfilePage + IndividualPhysician + practicesAt trỏ về Organization Kangnam (theo KF-15) | O37: /doi-ngu-bac-si/ | P37: R4 · Chỉ gắn bác sĩ đúng chuyên khoa + đã đăng ký hành nghề tại cơ sở (KF-11 N.6, KF-02)
A38: C14-04 | B38: C14 · Thực thể thương hiệu & bác sĩ (GEO Entity) ⭐⭐ | C38: S3 · CÂN NHẮC & NỖI SỢ (Warm→Hot) | D38: Bác sĩ Richard Huy là ai, chuyên về lĩnh vực gì? | E38: Thực thể | F38: Hot | G38: P1 | H38: Cao | I38: CORE 80/20 | J38: =IFERROR(INDEX($U$5:$U$19,MATCH(LEFT(B38,3),$S$5:$S$19,0)),"") -> A · CORE 80/20 | K38: 34 | L38: =IF(H38="Cao",3,IF(H38="TB",2,1))*IF(F38="Hot",3,IF(F38="Warm",2,1))*(4-VALUE(RIGHT(G38,1)))*IFERROR(INDEX($V$5:$V$19,MATCH(LEFT(B38,3),$S$5:$S$19,0)),1) -> 54 | M38: bác sĩ richard huy | N38: Trang hồ sơ dùng tên thương hiệu 'Richard Huy' làm tên hiển thị + tên khai sinh ở author box (kiến trúc 3 tầng tên — KF-15 Phần 2) | O38: /doi-ngu-bac-si/ | P38: R4 · Chỉ gắn bác sĩ đúng chuyên khoa + đã đăng ký hành nghề tại cơ sở (KF-11 N.6, KF-02)
A39: C14-05 | B39: C14 · Thực thể thương hiệu & bác sĩ (GEO Entity) ⭐⭐ | C39: S3 · CÂN NHẮC & NỖI SỢ (Warm→Hot) | D39: Bác sĩ nào ở Kangnam phụ trách phẫu thuật thẩm mỹ mũi? | E39: Thực thể | F39: Hot | G39: P1 | H39: Cao | I39: CORE 80/20 | J39: =IFERROR(INDEX($U$5:$U$19,MATCH(LEFT(B39,3),$S$5:$S$19,0)),"") -> A · CORE 80/20 | K39: 35 | L39: =IF(H39="Cao",3,IF(H39="TB",2,1))*IF(F39="Hot",3,IF(F39="Warm",2,1))*(4-VALUE(RIGHT(G39,1)))*IFERROR(INDEX($V$5:$V$19,MATCH(LEFT(B39,3),$S$5:$S$19,0)),1) -> 54 | M39: thẩm mỹ kangnam bác sĩ mũi | N39: CHỈ nêu bác sĩ đã xác minh chuyên khoa trong KF-02; bác sĩ [CẦN XÁC MINH] tuyệt đối không gắn vào dịch vụ mũi | O39: /doi-ngu-bac-si/ | P39: R4 · KF-02 quy tắc tuyệt đối + KF-11 N.6 — sai chuyên khoa là rủi ro phạt cao
A40: C14-07 | B40: C14 · Thực thể thương hiệu & bác sĩ (GEO Entity) ⭐⭐ | C40: S3 · CÂN NHẮC & NỖI SỢ (Warm→Hot) | D40: Kangnam có phòng mổ và ekip gây mê riêng không? | E40: Kiểm chứng | F40: Hot | G40: P1 | H40: Cao | I40: CORE 80/20 | J40: =IFERROR(INDEX($U$5:$U$19,MATCH(LEFT(B40,3),$S$5:$S$19,0)),"") -> A · CORE 80/20 | K40: 36 | L40: =IF(H40="Cao",3,IF(H40="TB",2,1))*IF(F40="Hot",3,IF(F40="Warm",2,1))*(4-VALUE(RIGHT(G40,1)))*IFERROR(INDEX($V$5:$V$19,MATCH(LEFT(B40,3),$S$5:$S$19,0)),1) -> 54 | M40: thẩm mỹ kangnam phòng mổ | N40: Trình bày năng lực: phòng mổ, thiết bị có số lưu hành, ekip gây mê hồi sức, quy trình cấp cứu | O40: /dich-vu/nang-mui/nang-mui-o-dau-dep/ | P40: R7 · Chỉ nêu thiết bị cơ sở thực sự có, đúng số lưu hành (KF-11 N.2)
A41: C14-09 | B41: C14 · Thực thể thương hiệu & bác sĩ (GEO Entity) ⭐⭐ | C41: S3 · CÂN NHẮC & NỖI SỢ (Warm→Hot) | D41: Kangnam có nhận sửa mũi hỏng do nơi khác làm không? | E41: Quy trình | F41: Hot | G41: P1 | H41: Cao | I41: CORE 80/20 | J41: =IFERROR(INDEX($U$5:$U$19,MATCH(LEFT(B41,3),$S$5:$S$19,0)),"") -> A · CORE 80/20 | K41: 37 | L41: =IF(H41="Cao",3,IF(H41="TB",2,1))*IF(F41="Hot",3,IF(F41="Warm",2,1))*(4-VALUE(RIGHT(G41,1)))*IFERROR(INDEX($V$5:$V$19,MATCH(LEFT(B41,3),$S$5:$S$19,0)),1) -> 54 | M41: thẩm mỹ kangnam sửa mũi hỏng | N41: Câu trả lời khẳng định + quy trình tiếp nhận — kết nối trực tiếp với cụm C11 giá trị cao nhất | O41: Trang con: Khắc phục mũi hỏng (pillar mũi) | P41: R6 · KHÔNG so sánh trực tiếp/nêu tên đối thủ — chỉ đưa bộ tiêu chí khách quan
A42: C14-11 | B42: C14 · Thực thể thương hiệu & bác sĩ (GEO Entity) ⭐⭐ | C42: S3 · CÂN NHẮC & NỖI SỢ (Warm→Hot) | D42: Địa chỉ và số điện thoại Kangnam Hà Nội là gì? | E42: Local | F42: Hot | G42: P1 | H42: Cao | I42: CORE 80/20 | J42: =IFERROR(INDEX($U$5:$U$19,MATCH(LEFT(B42,3),$S$5:$S$19,0)),"") -> A · CORE 80/20 | K42: 38 | L42: =IF(H42="Cao",3,IF(H42="TB",2,1))*IF(F42="Hot",3,IF(F42="Warm",2,1))*(4-VALUE(RIGHT(G42,1)))*IFERROR(INDEX($V$5:$V$19,MATCH(LEFT(B42,3),$S$5:$S$19,0)),1) -> 54 | M42: thẩm mỹ kangnam hà nội | N42: NAP tuyệt đối nhất quán trên website, Google Business Profile, mạng xã hội, các trang danh bạ — đây là tín hiệu local AI dùng trực tiếp | O42: /dich-vu/nang-mui/nang-mui-o-dau-dep/ | P42: R9 · Nội dung dịch vụ KCB cần Giấy xác nhận nội dung QC tại Sở Y tế (KF-11)
...

Sheet Mũi- Prompt do luong GEO
B1: ID | C1: CỤM CHỦ ĐỀ | D1: GIAI ĐOẠN | E1: TRUY VẤN KHÁCH GÕ VÀO AI | F1: GÓC HỎI (fan-out) | G1: NHIỆT ĐỘ | H1: ƯU TIÊN | I1: GIÁ TRỊ DT | J1: NHÓM 80/20 | K1: TẦNG ƯU TIÊN | L1: THỨ TỰ TRIỂN KHAI (CORE) | M1: ĐIỂM ƯU TIÊN | N1: TỪ KHOÁ ƯU TIÊN (đề xuất) | O1: KHỐI TRẢ LỜI CẦN CÓ (brief giao content) | P1: TRANG ĐÍCH KANGNAM (KF-04) | Q1: RÀO PHÁP LÝ (KF-11) | S1: ChatGPT | T1: Gemini | U1: AI Overview | V1: ĐỐI THỦ ĐƯỢC AI NHẮC (ghi chú)
R2: x | S2: =COUNTIFS(S3:S72,"yes") -> 19 | T2: =COUNTIFS(T3:T72,"yes") -> 33 | U2: =COUNTIFS(U3:U72,"yes") -> 22 | X2: x | Y2: x
A3: 4 | B3: C11-04 | C3: C11 · Sửa mũi hỏng & tái phẫu thuật ⭐⭐⭐ | D3: S3 · CÂN NHẮC & NỖI SỢ (Warm→Hot) | E3: Sửa mũi hỏng lần 2, lần 3 có được không, có giới hạn số lần không | F3: Điều kiện | G3: Hot | H3: P1 | I3: Cao | J3: CORE 80/20 | K3: =IFERROR(INDEX($V$6:$V$20,MATCH(LEFT(C3,3),$U$6:$U$20,0)),"") | L3: 4 | M3: =IF(I3="Cao",3,IF(I3="TB",2,1))*IF(G3="Hot",3,IF(G3="Warm",2,1))*(4-VALUE(RIGHT(H3,1)))*IFERROR(INDEX($W$6:$W$20,MATCH(LEFT(C3,3),$U$6:$U$20,0)),1) -> 27 | N3: sửa mũi nhiều lần | O3: Không có giới hạn cứng nhưng mỗi lần khó hơn do sẹo và thiếu vật liệu tự thân; giải thích vì sao lần sửa đầu tiên nên làm đúng ngay | P3: Trang con: Khắc phục mũi hỏng (pillar mũi) | Q3: R1 · Không cam kết 100%/vĩnh viễn/không biến chứng (KF-11 NT.3) | R3: =VLOOKUP(E3,$X:$Y,2,0) -> #N/A
A4: 12 | B4: C11-12 | C4: C11 · Sửa mũi hỏng & tái phẫu thuật ⭐⭐⭐ | D4: S3 · CÂN NHẮC & NỖI SỢ (Warm→Hot) | E4: Sửa mũi hỏng ở nơi khác thì Kangnam có nhận không | F4: Quy trình | G4: Hot | H4: P1 | I4: Cao | J4: CORE 80/20 | K4: =IFERROR(INDEX($V$6:$V$20,MATCH(LEFT(C4,3),$U$6:$U$20,0)),"") | L4: 12 | M4: =IF(I4="Cao",3,IF(I4="TB",2,1))*IF(G4="Hot",3,IF(G4="Warm",2,1))*(4-VALUE(RIGHT(H4,1)))*IFERROR(INDEX($W$6:$W$20,MATCH(LEFT(C4,3),$U$6:$U$20,0)),1) -> 27 | N4: thẩm mỹ kangnam sửa mũi hỏng | O4: Khẳng định có tiếp nhận + quy trình đánh giá lại + tinh thần không phán xét nơi cũ — thái độ này quyết định chuyển đổi cụm giá trị cao nhất | P4: Trang con: Khắc phục mũi hỏng (pillar mũi) | Q4: R6 · KHÔNG so sánh trực tiếp/nêu tên đối thủ — chỉ đưa bộ tiêu chí khách quan | R4: =VLOOKUP(E4,$X:$Y,2,0) -> #N/A | S4: YES | T4: YES | U4: YES
A5: 9 | B5: C11-09 | C5: C11 · Sửa mũi hỏng & tái phẫu thuật ⭐⭐⭐ | D5: S3 · CÂN NHẮC & NỖI SỢ (Warm→Hot) | E5: Mũi sau nâng bị lệch sang một bên thì sửa lại có khó không | F5: Xử lý | G5: Hot | H5: P1 | I5: Cao | J5: CORE 80/20 | K5: =IFERROR(INDEX($V$6:$V$20,MATCH(LEFT(C5,3),$U$6:$U$20,0)),"") | L5: 9 | M5: =IF(I5="Cao",3,IF(I5="TB",2,1))*IF(G5="Hot",3,IF(G5="Warm",2,1))*(4-VALUE(RIGHT(H5,1)))*IFERROR(INDEX($W$6:$W$20,MATCH(LEFT(C5,3),$U$6:$U$20,0)),1) -> 27 | N5: sửa mũi bị lệch | O5: Phân biệt lệch do sụn, do trục xương, do bao xơ co kéo; mỗi nguyên nhân một hướng xử lý | P5: Trang con: Khắc phục mũi hỏng (pillar mũi) | Q5: R9 · Nội dung dịch vụ KCB cần Giấy xác nhận nội dung QC tại Sở Y tế (KF-11) | R5: =VLOOKUP(E5,$X:$Y,2,0) -> #N/A
A6: 7 | B6: C11-07 | C6: C11 · Sửa mũi hỏng & tái phẫu thuật ⭐⭐⭐ | D6: S3 · CÂN NHẮC & NỖI SỢ (Warm→Hot) | E6: Mũi bị nhiễm trùng sau nâng đã tháo sụn, giờ muốn làm lại thì chờ bao lâu | F6: Thời gian | G6: Hot | H6: P1 | I6: Cao | J6: CORE 80/20 | K6: =IFERROR(INDEX($V$6:$V$20,MATCH(LEFT(C6,3),$U$6:$U$20,0)),"") | L6: 7 | M6: =IF(I6="Cao",3,IF(I6="TB",2,1))*IF(G6="Hot",3,IF(G6="Warm",2,1))*(4-VALUE(RIGHT(H6,1)))*IFERROR(INDEX($W$6:$W$20,MATCH(LEFT(C6,3),$U$6:$U$20,0)),1) -> 27 | N6: tháo sụn bao lâu nâng lại | O6: Chờ tối thiểu 6 tháng sau khi hết nhiễm trùng hoàn toàn; cần cấy dịch xác định vi khuẩn trước khi tái phẫu thuật | P6: Trang con: Khắc phục mũi hỏng (pillar mũi) | Q6: R9 · Nội dung dịch vụ KCB cần Giấy xác nhận nội dung QC tại Sở Y tế (KF-11) | R6: =VLOOKUP(E6,$X:$Y,2,0) -> #N/A
A7: 31 | B7: C14-01 | C7: C14 · Thực thể thương hiệu & bác sĩ (GEO Entity) ⭐⭐ | D7: S3 · CÂN NHẮC & NỖI SỢ (Warm→Hot) | E7: Bệnh viện Thẩm mỹ Kangnam là bệnh viện nào, ở đâu, thuộc pháp nhân nào | F7: Thực thể | G7: Hot | H7: P1 | I7: Cao | J7: CORE 80/20 | K7: =IFERROR(INDEX($V$6:$V$20,MATCH(LEFT(C7,3),$U$6:$U$20,0)),"") | L7: 31 | M7: =IF(I7="Cao",3,IF(I7="TB",2,1))*IF(G7="Hot",3,IF(G7="Warm",2,1))*(4-VALUE(RIGHT(H7,1)))*IFERROR(INDEX($W$6:$W$20,MATCH(LEFT(C7,3),$U$6:$U$20,0)),1) -> 27 | N7: bệnh viện thẩm mỹ kangnam | O7: Trang 'Về chúng tôi' chuẩn thực thể: tên pháp nhân đầy đủ, MST, giấy phép, năm thành lập, địa chỉ từng chi nhánh, schema Organization + sameAs | P7: /chuyen-khoa/chuyen-khoa-tham-my-mui/ | Q7: R3 · Ghi ĐÚNG pháp nhân từng chi nhánh — điểm nóng KF-11 N.3 | R7: =VLOOKUP(E7,$X:$Y,2,0) -> #N/A | S7: YES | T7: YES | U7: YES
A8: 20 | B8: C08-05 | C8: C08 · Chọn cơ sở & bác sĩ ⭐⭐ | D8: S3 · CÂN NHẮC & NỖI SỢ (Warm→Hot) | E8: Nên nâng mũi ở bệnh viện hay ở thẩm mỹ viện | F8: So sánh | G8: Hot | H8: P1 | I8: Cao | J8: CORE 80/20 | K8: =IFERROR(INDEX($V$6:$V$20,MATCH(LEFT(C8,3),$U$6:$U$20,0)),"") | L8: 20 | M8: =IF(I8="Cao",3,IF(I8="TB",2,1))*IF(G8="Hot",3,IF(G8="Warm",2,1))*(4-VALUE(RIGHT(H8,1)))*IFERROR(INDEX($W$6:$W$20,MATCH(LEFT(C8,3),$U$6:$U$20,0)),1) -> 27 | N8: nâng mũi ở bệnh viện | O8: So sánh theo năng lực xử lý sự cố: phòng mổ đạt chuẩn, ekip gây mê, khả năng lưu bệnh nhân — nêu tiêu chí, không nêu tên cơ sở khác | P8: /chuyen-khoa/chuyen-khoa-tham-my-mui/ | Q8: R6 · KHÔNG so sánh trực tiếp/nêu tên đối thủ — chỉ đưa bộ tiêu chí khách quan | R8: =VLOOKUP(E8,$X:$Y,2,0) -> #N/A | U8: YES
